<?xml version="1.0" ?>
<!-- =================================================================================== -->
<!-- |    This document was autogenerated by xacro from hexapod.xacro                  | -->
<!-- |    EDITING THIS FILE BY HAND IS NOT RECOMMENDED                                 | -->
<!-- =================================================================================== -->
<robot name="hexapod">
  <gazebo>
    <plugin filename="libgazebo_ros_control.so" name="gazebo_ros_control">
      <robotNamespace>/hexapod</robotNamespace>
    </plugin>
  </gazebo>
  <!-- Sonar sensors for obstacle detection -->
  <!--xacro:macro name="sonar" params="suffix xyz rpy">
    <link name="sonar_${suffix}_link">
      <visual>
        <geometry>
          <cylinder radius="${infrared_size}" length="${infrared_size}"/>
        </geometry>
      </visual>
      <xacro:cylinder_inertial mass="${infrared_mass}" r="${infrared_size}" l="${infrared_size}"/>
    </link>
    <joint name="torso_sonar_${suffix}_joint" type="fixed">
      <parent link="torso"/>
      <child link="sonar_${suffix}_link"/>
      <origin xyz="${xyz}" rpy="${rpy}"/>
    </joint>

    <gazebo reference="sonar_${suffix}_link">
      <material>Gazebo/Black</material>
      <sensor type="ray" name="sonar_${suffix}">
        <pose>0 0 0 0 0 0</pose>
        <visualize>true</visualize>
        <update_rate>50</update_rate>
        <ray>
          <scan>
            <horizontal>
              <samples>10</samples>
              <resolution>1</resolution>
              <min_angle>-0.0873</min_angle>
              <max_angle>0.0873</max_angle>
            </horizontal>
            <vertical>
              <samples>10</samples>
              <resolution>1</resolution>
              <min_angle>-0.0873</min_angle>
              <max_angle>0.0873</max_angle>
            </vertical>
          </scan>
          <range>
            <min>0.1</min>
            <max>0.8</max>
            <resolution>0.002</resolution>
          </range>
        </ray>
        <plugin filename="libgazebo_ros_range.so" name="gazebo_ros_range">
          <gaussianNoise>0.005</gaussianNoise>
          <alwaysOn>true</alwaysOn>
          <updateRate>50</updateRate>
          <topicName>sensor/sonar_${suffix}</topicName>
          <frameName>sonar_${suffix}_link</frameName>
          <visualize>true</visualize>
          <radiation>infrared</radiation>
          <fov>0.02</fov>
        </plugin>
      </sensor>
    </gazebo>

    <gazebo reference="torso_sonar_${suffix}_joint">
      <disableFixedJointLumping>true</disableFixedJointLumping>
    </gazebo>
  </xacro:macro-->
  <!-- Hexapod -->
  <link name="dummy_link">
    <visual>
      <origin rpy="0 0 0" xyz="0 0 6.0"/>
      <geometry>
        <box size="0.01 0.01 0.01"/>
      </geometry>
      <material name="black"/>
    </visual>
    <gazebo reference="dummy_link">
      <material>Gazebo/Black</material>
    </gazebo>
  </link>
  <link name="torso">
    <visual>
      <geometry>
        <box size="0.12 0.2 0.056"/>
      </geometry>
    </visual>
    <collision>
      <geometry>
        <box size="0.12 0.2 0.056"/>
      </geometry>
    </collision>
    <inertial>
      <mass value="0.7"/>
      <inertia ixx="0.002516" ixy="0.0" ixz="0.0" iyy="0.001023" iyz="0.0" izz="0.003173"/>
    </inertial>
  </link>
  <joint name="dummy_base_joint" type="fixed">
    <parent link="dummy_link"/>
    <child link="torso"/>
    <origin rpy="0 0 0" xyz="0 0 0.5943080000000001"/>
  </joint>
  <gazebo reference="torso">
    <material>Gazebo/LightGrey</material>
  </gazebo>
  <!-- IMU sensor -->
  <!--link name="imu_link">
    <visual>
      <geometry>
        <box size="${imu_size} ${imu_size} ${imu_size}"/>
      </geometry>
    </visual>
    <collision>
      <geometry>
        <box size="${imu_size} ${imu_size} ${imu_size}"/>
      </geometry>
    </collision>
    <inertial>
        <mass value="${imu_mass}" />
        <inertia ixx="${(1/12) * imu_mass * (imu_size * imu_size + imu_size * imu_size)}" ixy="0.0" ixz="0.0"
                 iyy="${(1/12) * imu_mass * (imu_size * imu_size + imu_size * imu_size)}" iyz="0.0"
                 izz="${(1/12) * imu_mass * (imu_size * imu_size + imu_size * imu_size)}" />
    </inertial>
  </link>
  <joint name="torso_imu_joint" type="fixed">
    <parent link="torso"/>
    <child link="imu_link"/>
    <origin xyz="0 0 ${(body_z_length/2.0)+(imu_size/2.0)}" rpy="0 0 0"/>
  </joint>
  <gazebo reference="imu_link">
    <material>Gazebo/Orange</material>
    <gravity>true</gravity>
    <sensor name="imu_sensor" type="imu">
      <always_on>true</always_on>
      <update_rate>100</update_rate>
      <visualize>true</visualize>
      <topic>__default_topic__</topic>
      <plugin filename="libgazebo_ros_imu_sensor.so" name="imu_plugin">
        <robotNamespace>/hexapod</robotNamespace>
        <topicName>imu</topicName>
        <bodyName>imu_link</bodyName>
        <updateRateHZ>100.0</updateRateHZ>
        <gaussianNoise>0.0</gaussianNoise>
        <xyzOffset>0 0 0</xyzOffset>
        <rpyOffset>0 0 0</rpyOffset>
        <frameName>imu_link</frameName>
      </plugin>
      <pose>0 0 0 0 0 0</pose>
    </sensor>
  </gazebo>

  <gazebo reference="torso_imu_joint">
    <disableFixedJointLumping>true</disableFixedJointLumping>
  </gazebo-->
  <!-- Sonar/IR sensor for height estimation -->
  <!--link name="infrared_link">
    <visual>
      <geometry>
        <cylinder radius="${infrared_size}" length="${infrared_size}"/>
      </geometry>
    </visual>
    <xacro:cylinder_inertial mass="${infrared_mass}" r="${infrared_size}" l="${infrared_size}"/>
  </link>
  <joint name="torso_infrared_joint" type="fixed">
    <parent link="torso"/>
    <child link="infrared_link"/>
    <origin xyz="0 0 ${-(body_z_length/2.0)-(infrared_size)}" rpy="${pi/2.0} ${pi/2.0} 0"/>
  </joint>
  <gazebo reference="infrared_link">
    <material>Gazebo/Black</material>
    <sensor type="ray" name="infrared_sensor">
      <pose>0 0 0 0 0 0</pose>
      <visualize>true</visualize>
      <update_rate>50</update_rate>
      <ray>
        <scan>
          <horizontal>
            <samples>10</samples>
            <resolution>1</resolution>
            <min_angle>-0.14835</min_angle>
            <max_angle>0.14835</max_angle>
          </horizontal>
          <vertical>
            <samples>10</samples>
            <resolution>1</resolution>
            <min_angle>-0.14835</min_angle>
            <max_angle>0.14835</max_angle>
          </vertical>
        </scan>
        <range>
          <min>0.001</min>
          <max>2</max>
          <resolution>0.002</resolution>
        </range>
      </ray>
      <plugin filename="libgazebo_ros_range.so" name="gazebo_ros_range">
        <gaussianNoise>0.005</gaussianNoise>
        <alwaysOn>true</alwaysOn>
        <updateRate>50</updateRate>
        <topicName>sensor/ir</topicName>
        <frameName>infrared_link</frameName>
        <visualize>true</visualize>
        <radiation>infrared</radiation>
        <fov>0.02</fov>
      </plugin>
    </sensor>
  </gazebo>

  <gazebo reference="torso_infrared_joint">
    <disableFixedJointLumping>true</disableFixedJointLumping>
  </gazebo-->
  <!-- Macro function to placed sonars -->
  <!-- xacro:sonar suffix="1" xyz="0 ${(body_y_length/2.0) - infrared_size} ${(body_z_length/2.0)+(infrared_size/2.0)}" rpy="0 0 ${pi/2.0}"/-->
  <!-- gazebo ros joint state pub plugin -->
  <gazebo>
    <plugin filename="libgazebo_ros_joint_state_publisher.so" name="joint_state_publisher">
      <robotNamespace>/hexapod</robotNamespace>
      <jointName>tc_1, tc_2, tc_3, tc_4, tc_5, tc_6, ctr_1, ctr_2, ctr_3, ctr_4, ctr_5, ctr_6, fti_1, fti_2, fti_3, fti_4, fti_5, fti_6</jointName>
      <updateRate>50</updateRate>
      <alwaysOn>true</alwaysOn>
    </plugin>
  </gazebo>
  <link name="coxa_1">
    <visual>
      <origin rpy="0 0 0" xyz="0.0319375 0 0"/>
      <geometry>
        <box size="0.063875 0.04 0.04"/>
      </geometry>
    </visual>
    <collision>
      <origin rpy="0 0 0" xyz="0.0319375 0 0"/>
      <geometry>
        <box size="0.063875 0.04 0.04"/>
      </geometry>
    </collision>
    <inertial>
      <origin rpy="0 0 0" xyz="0.0319375 0 0"/>
      <mass value="0.081"/>
      <inertia ixx="0.0000216" ixy="0.0" ixz="0.0" iyy="0.0000383401" iyz="0.0" izz="0.0000383401"/>
    </inertial>
  </link>
  <joint name="tc_1" type="revolute">
    <axis xyz="0 0 1"/>
    <parent link="torso"/>
    <child link="coxa_1"/>
    <origin rpy="0 0 0.0" xyz="0.06 0.0 0"/>
    <limit effort="1.89" lower="-0.6108652381980153" upper="0.6108652381980153" velocity="6.544984694978735"/>
    <dynamics friction="0.0"/>
  </joint>
  <gazebo reference="coxa_1">
    <material>Gazebo/LightGrey</material>
  </gazebo>
  <gazebo reference="tc_1">
    <provideFeedback>true</provideFeedback>
  </gazebo>
  <gazebo>
    <plugin filename="libgazebo_ros_ft_sensor.so" name="torque_sensor_tc_1">
      <updateRate>50.0</updateRate>
      <topicName>torque_tc_1</topicName>
      <jointName>tc_1</jointName>
    </plugin>
  </gazebo>
  <transmission name="j_tc_1">
    <type>transmission_interface/SimpleTransmission</type>
    <joint name="tc_1">
      <hardwareInterface>hardware_interface/EffortJointInterface</hardwareInterface>
    </joint>
    <actuator name="motor_tc_1">
      <hardwareInterface>hardware_interface/EffortJointInterface</hardwareInterface>
      <mechanicalReduction>1</mechanicalReduction>
    </actuator>
  </transmission>
  <link name="femur_1">
    <visual>
      <origin rpy="0 0 0" xyz="0.04 0 0"/>
      <geometry>
        <box size="0.08 0.04 0.04"/>
      </geometry>
    </visual>
    <collision>
      <origin rpy="0 0 0" xyz="0.04 0 0"/>
      <geometry>
        <box size="0.08 0.04 0.04"/>
      </geometry>
    </collision>
    <inertial>
      <origin rpy="0 0 0" xyz="0.04 0 0"/>
      <mass value="0.136"/>
      <inertia ixx="0.0000362667" ixy="0.0" ixz="0.0" iyy="0.0000906667" iyz="0.0" izz="0.0000906667"/>
    </inertial>
  </link>
  <joint name="ctr_1" type="revolute">
    <axis xyz="0 -1 0"/>
    <parent link="coxa_1"/>
    <child link="femur_1"/>
    <origin rpy="0 0 0" xyz="0.063875 0 0"/>
    <limit effort="1.89" lower="-1.4835298641951802" upper="1.4835298641951802" velocity="6.544984694978735"/>
    <dynamics friction="0.0"/>
  </joint>
  <gazebo reference="femur_1">
    <material>Gazebo/LightGrey</material>
  </gazebo>
  <gazebo reference="ctr_1">
    <provideFeedback>true</provideFeedback>
  </gazebo>
  <gazebo>
    <plugin filename="libgazebo_ros_ft_sensor.so" name="torque_sensor_ctr_1">
      <updateRate>50.0</updateRate>
      <topicName>torque_ctr_1</topicName>
      <jointName>ctr_1</jointName>
    </plugin>
  </gazebo>
  <transmission name="j_ctr_1">
    <type>transmission_interface/SimpleTransmission</type>
    <joint name="ctr_1">
      <hardwareInterface>hardware_interface/EffortJointInterface</hardwareInterface>
    </joint>
    <actuator name="motor_ctr_1">
      <hardwareInterface>hardware_interface/EffortJointInterface</hardwareInterface>
      <mechanicalReduction>1</mechanicalReduction>
    </actuator>
  </transmission>
  <link name="tibia_1">
    <visual>
      <origin rpy="0 0 0" xyz="0 0 -0.057154"/>
      <geometry>
        <box size="0.04 0.04 0.114308"/>
      </geometry>
    </visual>
    <collision>
      <origin rpy="0 0 0" xyz="0 0 -0.057154"/>
      <geometry>
        <box size="0.04 0.04 0.114308"/>
      </geometry>
    </collision>
    <inertial>
      <origin rpy="0 0 0" xyz="0 0 -0.057154"/>
      <mass value="0.01338"/>
      <inertia ixx="0.0000163529" ixy="0.0" ixz="0.0" iyy="0.0000163529" iyz="0.0" izz="0.000003568"/>
    </inertial>
  </link>
  <joint name="fti_1" type="revolute">
    <axis xyz="0 -1 0"/>
    <parent link="femur_1"/>
    <child link="tibia_1"/>
    <origin rpy="0 0 0" xyz="0.08 0 0"/>
    <limit effort="1.89" lower="-1.4835298641951802" upper="1.4835298641951802" velocity="6.544984694978735"/>
    <dynamics friction="0.0"/>
  </joint>
  <gazebo reference="tibia_1">
    <material>Gazebo/LightGrey</material>
  </gazebo>
  <gazebo reference="fti_1">
    <provideFeedback>true</provideFeedback>
  </gazebo>
  <gazebo>
    <plugin filename="libgazebo_ros_ft_sensor.so" name="torque_sensor_fti_1">
      <updateRate>50.0</updateRate>
      <topicName>torque_fti_1</topicName>
      <jointName>fti_1</jointName>
    </plugin>
  </gazebo>
  <transmission name="j_fti_1">
    <type>transmission_interface/SimpleTransmission</type>
    <joint name="fti_1">
      <hardwareInterface>hardware_interface/EffortJointInterface</hardwareInterface>
    </joint>
    <actuator name="motor_fti_1">
      <hardwareInterface>hardware_interface/EffortJointInterface</hardwareInterface>
      <mechanicalReduction>1</mechanicalReduction>
    </actuator>
  </transmission>
  <link name="foot_1">
    <visual>
      <origin rpy="0 0 0" xyz="0 0 0"/>
      <geometry>
        <sphere radius="0.02"/>
      </geometry>
    </visual>
    <collision>
      <origin rpy="0 0 0" xyz="0 0 0"/>
      <geometry>
        <sphere radius="0.02"/>
      </geometry>
    </collision>
    <inertial>
      <origin rpy="0 0 0" xyz="0 0 0"/>
      <mass value="0.00892"/>
      <inertia ixx="0.0000057088" ixy="0.0" ixz="0.0" iyy="0.0000057088" iyz="0.0" izz="0.0000057088"/>
    </inertial>
  </link>
  <joint name="foot_1_joint" type="fixed">
    <parent link="tibia_1"/>
    <child link="foot_1"/>
    <origin rpy="0 0 0" xyz="0 0 -0.134308"/>
  </joint>
  <gazebo reference="foot_1_joint">
    <disableFixedJointLumping>true</disableFixedJointLumping>
  </gazebo>
  <gazebo reference="foot_1">
    <kp>1e06</kp>
    <kd>1.0</kd>
    <maxVel>0.0</maxVel>
    <minDepth>0.003</minDepth>
    <material>Gazebo/LightGrey</material>
    <collision name="foot_1_collision">
      <geometry>
        <sphere>
          <radius>0.02</radius>
        </sphere>
      </geometry>
      <surface>
        <friction>
          <ode>
            <solver>
              <friction_model>cone_model</friction_model>
              <mu>1.0</mu>
            </solver>
          </ode>
        </friction>
      </surface>
    </collision>
    <!-- Bumper sensor for contact detection -->
    <sensor name="contact_sensor_1" type="contact">
      <always_on>true</always_on>
      <contact>
        <collision>foot_1_collision</collision>
      </contact>
      <plugin filename="libgazebo_ros_bumper.so" name="foot_1_plugin">
        <updateRate>50</updateRate>
        <always_on>true</always_on>
        <bumperTopicName>foot_1_bumper</bumperTopicName>
        <frameName>world</frameName>
      </plugin>
    </sensor>
  </gazebo>
  <link name="coxa_2">
    <visual>
      <origin rpy="0 0 0" xyz="0.0319375 0 0"/>
      <geometry>
        <box size="0.063875 0.04 0.04"/>
      </geometry>
    </visual>
    <collision>
      <origin rpy="0 0 0" xyz="0.0319375 0 0"/>
      <geometry>
        <box size="0.063875 0.04 0.04"/>
      </geometry>
    </collision>
    <inertial>
      <origin rpy="0 0 0" xyz="0.0319375 0 0"/>
      <mass value="0.081"/>
      <inertia ixx="0.0000216" ixy="0.0" ixz="0.0" iyy="0.0000383401" iyz="0.0" izz="0.0000383401"/>
    </inertial>
  </link>
  <joint name="tc_2" type="revolute">
    <axis xyz="0 0 1"/>
    <parent link="torso"/>
    <child link="coxa_2"/>
    <origin rpy="0 0 0.7853981633974483" xyz="0.06 0.1 0"/>
    <limit effort="1.89" lower="-0.6108652381980153" upper="0.6108652381980153" velocity="6.544984694978735"/>
    <dynamics friction="0.0"/>
  </joint>
  <gazebo reference="coxa_2">
    <material>Gazebo/LightGrey</material>
  </gazebo>
  <gazebo reference="tc_2">
    <provideFeedback>true</provideFeedback>
  </gazebo>
  <gazebo>
    <plugin filename="libgazebo_ros_ft_sensor.so" name="torque_sensor_tc_2">
      <updateRate>50.0</updateRate>
      <topicName>torque_tc_2</topicName>
      <jointName>tc_2</jointName>
    </plugin>
  </gazebo>
  <transmission name="j_tc_2">
    <type>transmission_interface/SimpleTransmission</type>
    <joint name="tc_2">
      <hardwareInterface>hardware_interface/EffortJointInterface</hardwareInterface>
    </joint>
    <actuator name="motor_tc_2">
      <hardwareInterface>hardware_interface/EffortJointInterface</hardwareInterface>
      <mechanicalReduction>1</mechanicalReduction>
    </actuator>
  </transmission>
  <link name="femur_2">
    <visual>
      <origin rpy="0 0 0" xyz="0.04 0 0"/>
      <geometry>
        <box size="0.08 0.04 0.04"/>
      </geometry>
    </visual>
    <collision>
      <origin rpy="0 0 0" xyz="0.04 0 0"/>
      <geometry>
        <box size="0.08 0.04 0.04"/>
      </geometry>
    </collision>
    <inertial>
      <origin rpy="0 0 0" xyz="0.04 0 0"/>
      <mass value="0.136"/>
      <inertia ixx="0.0000362667" ixy="0.0" ixz="0.0" iyy="0.0000906667" iyz="0.0" izz="0.0000906667"/>
    </inertial>
  </link>
  <joint name="ctr_2" type="revolute">
    <axis xyz="0 -1 0"/>
    <parent link="coxa_2"/>
    <child link="femur_2"/>
    <origin rpy="0 0 0" xyz="0.063875 0 0"/>
    <limit effort="1.89" lower="-1.4835298641951802" upper="1.4835298641951802" velocity="6.544984694978735"/>
    <dynamics friction="0.0"/>
  </joint>
  <gazebo reference="femur_2">
    <material>Gazebo/LightGrey</material>
  </gazebo>
  <gazebo reference="ctr_2">
    <provideFeedback>true</provideFeedback>
  </gazebo>
  <gazebo>
    <plugin filename="libgazebo_ros_ft_sensor.so" name="torque_sensor_ctr_2">
      <updateRate>50.0</updateRate>
      <topicName>torque_ctr_2</topicName>
      <jointName>ctr_2</jointName>
    </plugin>
  </gazebo>
  <transmission name="j_ctr_2">
    <type>transmission_interface/SimpleTransmission</type>
    <joint name="ctr_2">
      <hardwareInterface>hardware_interface/EffortJointInterface</hardwareInterface>
    </joint>
    <actuator name="motor_ctr_2">
      <hardwareInterface>hardware_interface/EffortJointInterface</hardwareInterface>
      <mechanicalReduction>1</mechanicalReduction>
    </actuator>
  </transmission>
  <link name="tibia_2">
    <visual>
      <origin rpy="0 0 0" xyz="0 0 -0.057154"/>
      <geometry>
        <box size="0.04 0.04 0.114308"/>
      </geometry>
    </visual>
    <collision>
      <origin rpy="0 0 0" xyz="0 0 -0.057154"/>
      <geometry>
        <box size="0.04 0.04 0.114308"/>
      </geometry>
    </collision>
    <inertial>
      <origin rpy="0 0 0" xyz="0 0 -0.057154"/>
      <mass value="0.01338"/>
      <inertia ixx="0.0000163529" ixy="0.0" ixz="0.0" iyy="0.0000163529" iyz="0.0" izz="0.000003568"/>
    </inertial>
  </link>
  <joint name="fti_2" type="revolute">
    <axis xyz="0 -1 0"/>
    <parent link="femur_2"/>
    <child link="tibia_2"/>
    <origin rpy="0 0 0" xyz="0.08 0 0"/>
    <limit effort="1.89" lower="-1.4835298641951802" upper="1.4835298641951802" velocity="6.544984694978735"/>
    <dynamics friction="0.0"/>
  </joint>
  <gazebo reference="tibia_2">
    <material>Gazebo/LightGrey</material>
  </gazebo>
  <gazebo reference="fti_2">
    <provideFeedback>true</provideFeedback>
  </gazebo>
  <gazebo>
    <plugin filename="libgazebo_ros_ft_sensor.so" name="torque_sensor_fti_2">
      <updateRate>50.0</updateRate>
      <topicName>torque_fti_2</topicName>
      <jointName>fti_2</jointName>
    </plugin>
  </gazebo>
  <transmission name="j_fti_2">
    <type>transmission_interface/SimpleTransmission</type>
    <joint name="fti_2">
      <hardwareInterface>hardware_interface/EffortJointInterface</hardwareInterface>
    </joint>
    <actuator name="motor_fti_2">
      <hardwareInterface>hardware_interface/EffortJointInterface</hardwareInterface>
      <mechanicalReduction>1</mechanicalReduction>
    </actuator>
  </transmission>
  <link name="foot_2">
    <visual>
      <origin rpy="0 0 0" xyz="0 0 0"/>
      <geometry>
        <sphere radius="0.02"/>
      </geometry>
    </visual>
    <collision>
      <origin rpy="0 0 0" xyz="0 0 0"/>
      <geometry>
        <sphere radius="0.02"/>
      </geometry>
    </collision>
    <inertial>
      <origin rpy="0 0 0" xyz="0 0 0"/>
      <mass value="0.00892"/>
      <inertia ixx="0.0000057088" ixy="0.0" ixz="0.0" iyy="0.0000057088" iyz="0.0" izz="0.0000057088"/>
    </inertial>
  </link>
  <joint name="foot_2_joint" type="fixed">
    <parent link="tibia_2"/>
    <child link="foot_2"/>
    <origin rpy="0 0 0" xyz="0 0 -0.134308"/>
  </joint>
  <gazebo reference="foot_2_joint">
    <disableFixedJointLumping>true</disableFixedJointLumping>
  </gazebo>
  <gazebo reference="foot_2">
    <kp>1e06</kp>
    <kd>1.0</kd>
    <maxVel>0.0</maxVel>
    <minDepth>0.003</minDepth>
    <material>Gazebo/LightGrey</material>
    <collision name="foot_2_collision">
      <geometry>
        <sphere>
          <radius>0.02</radius>
        </sphere>
      </geometry>
      <surface>
        <friction>
          <ode>
            <solver>
              <friction_model>cone_model</friction_model>
              <mu>1.0</mu>
            </solver>
          </ode>
        </friction>
      </surface>
    </collision>
    <!-- Bumper sensor for contact detection -->
    <sensor name="contact_sensor_2" type="contact">
      <always_on>true</always_on>
      <contact>
        <collision>foot_2_collision</collision>
      </contact>
      <plugin filename="libgazebo_ros_bumper.so" name="foot_2_plugin">
        <updateRate>50</updateRate>
        <always_on>true</always_on>
        <bumperTopicName>foot_2_bumper</bumperTopicName>
        <frameName>world</frameName>
      </plugin>
    </sensor>
  </gazebo>
  <link name="coxa_3">
    <visual>
      <origin rpy="0 0 0" xyz="0.0319375 0 0"/>
      <geometry>
        <box size="0.063875 0.04 0.04"/>
      </geometry>
    </visual>
    <collision>
      <origin rpy="0 0 0" xyz="0.0319375 0 0"/>
      <geometry>
        <box size="0.063875 0.04 0.04"/>
      </geometry>
    </collision>
    <inertial>
      <origin rpy="0 0 0" xyz="0.0319375 0 0"/>
      <mass value="0.081"/>
      <inertia ixx="0.0000216" ixy="0.0" ixz="0.0" iyy="0.0000383401" iyz="0.0" izz="0.0000383401"/>
    </inertial>
  </link>
  <joint name="tc_3" type="revolute">
    <axis xyz="0 0 1"/>
    <parent link="torso"/>
    <child link="coxa_3"/>
    <origin rpy="0 0 2.356194490192345" xyz="-0.06 0.1 0"/>
    <limit effort="1.89" lower="-0.6108652381980153" upper="0.6108652381980153" velocity="6.544984694978735"/>
    <dynamics friction="0.0"/>
  </joint>
  <gazebo reference="coxa_3">
    <material>Gazebo/LightGrey</material>
  </gazebo>
  <gazebo reference="tc_3">
    <provideFeedback>true</provideFeedback>
  </gazebo>
  <gazebo>
    <plugin filename="libgazebo_ros_ft_sensor.so" name="torque_sensor_tc_3">
      <updateRate>50.0</updateRate>
      <topicName>torque_tc_3</topicName>
      <jointName>tc_3</jointName>
    </plugin>
  </gazebo>
  <transmission name="j_tc_3">
    <type>transmission_interface/SimpleTransmission</type>
    <joint name="tc_3">
      <hardwareInterface>hardware_interface/EffortJointInterface</hardwareInterface>
    </joint>
    <actuator name="motor_tc_3">
      <hardwareInterface>hardware_interface/EffortJointInterface</hardwareInterface>
      <mechanicalReduction>1</mechanicalReduction>
    </actuator>
  </transmission>
  <link name="femur_3">
    <visual>
      <origin rpy="0 0 0" xyz="0.04 0 0"/>
      <geometry>
        <box size="0.08 0.04 0.04"/>
      </geometry>
    </visual>
    <collision>
      <origin rpy="0 0 0" xyz="0.04 0 0"/>
      <geometry>
        <box size="0.08 0.04 0.04"/>
      </geometry>
    </collision>
    <inertial>
      <origin rpy="0 0 0" xyz="0.04 0 0"/>
      <mass value="0.136"/>
      <inertia ixx="0.0000362667" ixy="0.0" ixz="0.0" iyy="0.0000906667" iyz="0.0" izz="0.0000906667"/>
    </inertial>
  </link>
  <joint name="ctr_3" type="revolute">
    <axis xyz="0 -1 0"/>
    <parent link="coxa_3"/>
    <child link="femur_3"/>
    <origin rpy="0 0 0" xyz="0.063875 0 0"/>
    <limit effort="1.89" lower="-1.4835298641951802" upper="1.4835298641951802" velocity="6.544984694978735"/>
    <dynamics friction="0.0"/>
  </joint>
  <gazebo reference="femur_3">
    <material>Gazebo/LightGrey</material>
  </gazebo>
  <gazebo reference="ctr_3">
    <provideFeedback>true</provideFeedback>
  </gazebo>
  <gazebo>
    <plugin filename="libgazebo_ros_ft_sensor.so" name="torque_sensor_ctr_3">
      <updateRate>50.0</updateRate>
      <topicName>torque_ctr_3</topicName>
      <jointName>ctr_3</jointName>
    </plugin>
  </gazebo>
  <transmission name="j_ctr_3">
    <type>transmission_interface/SimpleTransmission</type>
    <joint name="ctr_3">
      <hardwareInterface>hardware_interface/EffortJointInterface</hardwareInterface>
    </joint>
    <actuator name="motor_ctr_3">
      <hardwareInterface>hardware_interface/EffortJointInterface</hardwareInterface>
      <mechanicalReduction>1</mechanicalReduction>
    </actuator>
  </transmission>
  <link name="tibia_3">
    <visual>
      <origin rpy="0 0 0" xyz="0 0 -0.057154"/>
      <geometry>
        <box size="0.04 0.04 0.114308"/>
      </geometry>
    </visual>
    <collision>
      <origin rpy="0 0 0" xyz="0 0 -0.057154"/>
      <geometry>
        <box size="0.04 0.04 0.114308"/>
      </geometry>
    </collision>
    <inertial>
      <origin rpy="0 0 0" xyz="0 0 -0.057154"/>
      <mass value="0.01338"/>
      <inertia ixx="0.0000163529" ixy="0.0" ixz="0.0" iyy="0.0000163529" iyz="0.0" izz="0.000003568"/>
    </inertial>
  </link>
  <joint name="fti_3" type="revolute">
    <axis xyz="0 -1 0"/>
    <parent link="femur_3"/>
    <child link="tibia_3"/>
    <origin rpy="0 0 0" xyz="0.08 0 0"/>
    <limit effort="1.89" lower="-1.4835298641951802" upper="1.4835298641951802" velocity="6.544984694978735"/>
    <dynamics friction="0.0"/>
  </joint>
  <gazebo reference="tibia_3">
    <material>Gazebo/LightGrey</material>
  </gazebo>
  <gazebo reference="fti_3">
    <provideFeedback>true</provideFeedback>
  </gazebo>
  <gazebo>
    <plugin filename="libgazebo_ros_ft_sensor.so" name="torque_sensor_fti_3">
      <updateRate>50.0</updateRate>
      <topicName>torque_fti_3</topicName>
      <jointName>fti_3</jointName>
    </plugin>
  </gazebo>
  <transmission name="j_fti_3">
    <type>transmission_interface/SimpleTransmission</type>
    <joint name="fti_3">
      <hardwareInterface>hardware_interface/EffortJointInterface</hardwareInterface>
    </joint>
    <actuator name="motor_fti_3">
      <hardwareInterface>hardware_interface/EffortJointInterface</hardwareInterface>
      <mechanicalReduction>1</mechanicalReduction>
    </actuator>
  </transmission>
  <link name="foot_3">
    <visual>
      <origin rpy="0 0 0" xyz="0 0 0"/>
      <geometry>
        <sphere radius="0.02"/>
      </geometry>
    </visual>
    <collision>
      <origin rpy="0 0 0" xyz="0 0 0"/>
      <geometry>
        <sphere radius="0.02"/>
      </geometry>
    </collision>
    <inertial>
      <origin rpy="0 0 0" xyz="0 0 0"/>
      <mass value="0.00892"/>
      <inertia ixx="0.0000057088" ixy="0.0" ixz="0.0" iyy="0.0000057088" iyz="0.0" izz="0.0000057088"/>
    </inertial>
  </link>
  <joint name="foot_3_joint" type="fixed">
    <parent link="tibia_3"/>
    <child link="foot_3"/>
    <origin rpy="0 0 0" xyz="0 0 -0.134308"/>
  </joint>
  <gazebo reference="foot_3_joint">
    <disableFixedJointLumping>true</disableFixedJointLumping>
  </gazebo>
  <gazebo reference="foot_3">
    <kp>1e06</kp>
    <kd>1.0</kd>
    <maxVel>0.0</maxVel>
    <minDepth>0.003</minDepth>
    <material>Gazebo/LightGrey</material>
    <collision name="foot_3_collision">
      <geometry>
        <sphere>
          <radius>0.02</radius>
        </sphere>
      </geometry>
      <surface>
        <friction>
          <ode>
            <solver>
              <friction_model>cone_model</friction_model>
              <mu>1.0</mu>
            </solver>
          </ode>
        </friction>
      </surface>
    </collision>
    <!-- Bumper sensor for contact detection -->
    <sensor name="contact_sensor_3" type="contact">
      <always_on>true</always_on>
      <contact>
        <collision>foot_3_collision</collision>
      </contact>
      <plugin filename="libgazebo_ros_bumper.so" name="foot_3_plugin">
        <updateRate>50</updateRate>
        <always_on>true</always_on>
        <bumperTopicName>foot_3_bumper</bumperTopicName>
        <frameName>world</frameName>
      </plugin>
    </sensor>
  </gazebo>
  <link name="coxa_4">
    <visual>
      <origin rpy="0 0 0" xyz="0.0319375 0 0"/>
      <geometry>
        <box size="0.063875 0.04 0.04"/>
      </geometry>
    </visual>
    <collision>
      <origin rpy="0 0 0" xyz="0.0319375 0 0"/>
      <geometry>
        <box size="0.063875 0.04 0.04"/>
      </geometry>
    </collision>
    <inertial>
      <origin rpy="0 0 0" xyz="0.0319375 0 0"/>
      <mass value="0.081"/>
      <inertia ixx="0.0000216" ixy="0.0" ixz="0.0" iyy="0.0000383401" iyz="0.0" izz="0.0000383401"/>
    </inertial>
  </link>
  <joint name="tc_4" type="revolute">
    <axis xyz="0 0 1"/>
    <parent link="torso"/>
    <child link="coxa_4"/>
    <origin rpy="0 0 3.141592653589793" xyz="-0.06 0.0 0"/>
    <limit effort="1.89" lower="-0.6108652381980153" upper="0.6108652381980153" velocity="6.544984694978735"/>
    <dynamics friction="0.0"/>
  </joint>
  <gazebo reference="coxa_4">
    <material>Gazebo/LightGrey</material>
  </gazebo>
  <gazebo reference="tc_4">
    <provideFeedback>true</provideFeedback>
  </gazebo>
  <gazebo>
    <plugin filename="libgazebo_ros_ft_sensor.so" name="torque_sensor_tc_4">
      <updateRate>50.0</updateRate>
      <topicName>torque_tc_4</topicName>
      <jointName>tc_4</jointName>
    </plugin>
  </gazebo>
  <transmission name="j_tc_4">
    <type>transmission_interface/SimpleTransmission</type>
    <joint name="tc_4">
      <hardwareInterface>hardware_interface/EffortJointInterface</hardwareInterface>
    </joint>
    <actuator name="motor_tc_4">
      <hardwareInterface>hardware_interface/EffortJointInterface</hardwareInterface>
      <mechanicalReduction>1</mechanicalReduction>
    </actuator>
  </transmission>
  <link name="femur_4">
    <visual>
      <origin rpy="0 0 0" xyz="0.04 0 0"/>
      <geometry>
        <box size="0.08 0.04 0.04"/>
      </geometry>
    </visual>
    <collision>
      <origin rpy="0 0 0" xyz="0.04 0 0"/>
      <geometry>
        <box size="0.08 0.04 0.04"/>
      </geometry>
    </collision>
    <inertial>
      <origin rpy="0 0 0" xyz="0.04 0 0"/>
      <mass value="0.136"/>
      <inertia ixx="0.0000362667" ixy="0.0" ixz="0.0" iyy="0.0000906667" iyz="0.0" izz="0.0000906667"/>
    </inertial>
  </link>
  <joint name="ctr_4" type="revolute">
    <axis xyz="0 -1 0"/>
    <parent link="coxa_4"/>
    <child link="femur_4"/>
    <origin rpy="0 0 0" xyz="0.063875 0 0"/>
    <limit effort="1.89" lower="-1.4835298641951802" upper="1.4835298641951802" velocity="6.544984694978735"/>
    <dynamics friction="0.0"/>
  </joint>
  <gazebo reference="femur_4">
    <material>Gazebo/LightGrey</material>
  </gazebo>
  <gazebo reference="ctr_4">
    <provideFeedback>true</provideFeedback>
  </gazebo>
  <gazebo>
    <plugin filename="libgazebo_ros_ft_sensor.so" name="torque_sensor_ctr_4">
      <updateRate>50.0</updateRate>
      <topicName>torque_ctr_4</topicName>
      <jointName>ctr_4</jointName>
    </plugin>
  </gazebo>
  <transmission name="j_ctr_4">
    <type>transmission_interface/SimpleTransmission</type>
    <joint name="ctr_4">
      <hardwareInterface>hardware_interface/EffortJointInterface</hardwareInterface>
    </joint>
    <actuator name="motor_ctr_4">
      <hardwareInterface>hardware_interface/EffortJointInterface</hardwareInterface>
      <mechanicalReduction>1</mechanicalReduction>
    </actuator>
  </transmission>
  <link name="tibia_4">
    <visual>
      <origin rpy="0 0 0" xyz="0 0 -0.057154"/>
      <geometry>
        <box size="0.04 0.04 0.114308"/>
      </geometry>
    </visual>
    <collision>
      <origin rpy="0 0 0" xyz="0 0 -0.057154"/>
      <geometry>
        <box size="0.04 0.04 0.114308"/>
      </geometry>
    </collision>
    <inertial>
      <origin rpy="0 0 0" xyz="0 0 -0.057154"/>
      <mass value="0.01338"/>
      <inertia ixx="0.0000163529" ixy="0.0" ixz="0.0" iyy="0.0000163529" iyz="0.0" izz="0.000003568"/>
    </inertial>
  </link>
  <joint name="fti_4" type="revolute">
    <axis xyz="0 -1 0"/>
    <parent link="femur_4"/>
    <child link="tibia_4"/>
    <origin rpy="0 0 0" xyz="0.08 0 0"/>
    <limit effort="1.89" lower="-1.4835298641951802" upper="1.4835298641951802" velocity="6.544984694978735"/>
    <dynamics friction="0.0"/>
  </joint>
  <gazebo reference="tibia_4">
    <material>Gazebo/LightGrey</material>
  </gazebo>
  <gazebo reference="fti_4">
    <provideFeedback>true</provideFeedback>
  </gazebo>
  <gazebo>
    <plugin filename="libgazebo_ros_ft_sensor.so" name="torque_sensor_fti_4">
      <updateRate>50.0</updateRate>
      <topicName>torque_fti_4</topicName>
      <jointName>fti_4</jointName>
    </plugin>
  </gazebo>
  <transmission name="j_fti_4">
    <type>transmission_interface/SimpleTransmission</type>
    <joint name="fti_4">
      <hardwareInterface>hardware_interface/EffortJointInterface</hardwareInterface>
    </joint>
    <actuator name="motor_fti_4">
      <hardwareInterface>hardware_interface/EffortJointInterface</hardwareInterface>
      <mechanicalReduction>1</mechanicalReduction>
    </actuator>
  </transmission>
  <link name="foot_4">
    <visual>
      <origin rpy="0 0 0" xyz="0 0 0"/>
      <geometry>
        <sphere radius="0.02"/>
      </geometry>
    </visual>
    <collision>
      <origin rpy="0 0 0" xyz="0 0 0"/>
      <geometry>
        <sphere radius="0.02"/>
      </geometry>
    </collision>
    <inertial>
      <origin rpy="0 0 0" xyz="0 0 0"/>
      <mass value="0.00892"/>
      <inertia ixx="0.0000057088" ixy="0.0" ixz="0.0" iyy="0.0000057088" iyz="0.0" izz="0.0000057088"/>
    </inertial>
  </link>
  <joint name="foot_4_joint" type="fixed">
    <parent link="tibia_4"/>
    <child link="foot_4"/>
    <origin rpy="0 0 0" xyz="0 0 -0.134308"/>
  </joint>
  <gazebo reference="foot_4_joint">
    <disableFixedJointLumping>true</disableFixedJointLumping>
  </gazebo>
  <gazebo reference="foot_4">
    <kp>1e06</kp>
    <kd>1.0</kd>
    <maxVel>0.0</maxVel>
    <minDepth>0.003</minDepth>
    <material>Gazebo/LightGrey</material>
    <collision name="foot_4_collision">
      <geometry>
        <sphere>
          <radius>0.02</radius>
        </sphere>
      </geometry>
      <surface>
        <friction>
          <ode>
            <solver>
              <friction_model>cone_model</friction_model>
              <mu>1.0</mu>
            </solver>
          </ode>
        </friction>
      </surface>
    </collision>
    <!-- Bumper sensor for contact detection -->
    <sensor name="contact_sensor_4" type="contact">
      <always_on>true</always_on>
      <contact>
        <collision>foot_4_collision</collision>
      </contact>
      <plugin filename="libgazebo_ros_bumper.so" name="foot_4_plugin">
        <updateRate>50</updateRate>
        <always_on>true</always_on>
        <bumperTopicName>foot_4_bumper</bumperTopicName>
        <frameName>world</frameName>
      </plugin>
    </sensor>
  </gazebo>
  <link name="coxa_5">
    <visual>
      <origin rpy="0 0 0" xyz="0.0319375 0 0"/>
      <geometry>
        <box size="0.063875 0.04 0.04"/>
      </geometry>
    </visual>
    <collision>
      <origin rpy="0 0 0" xyz="0.0319375 0 0"/>
      <geometry>
        <box size="0.063875 0.04 0.04"/>
      </geometry>
    </collision>
    <inertial>
      <origin rpy="0 0 0" xyz="0.0319375 0 0"/>
      <mass value="0.081"/>
      <inertia ixx="0.0000216" ixy="0.0" ixz="0.0" iyy="0.0000383401" iyz="0.0" izz="0.0000383401"/>
    </inertial>
  </link>
  <joint name="tc_5" type="revolute">
    <axis xyz="0 0 1"/>
    <parent link="torso"/>
    <child link="coxa_5"/>
    <origin rpy="0 0 -2.356194490192345" xyz="-0.06 -0.1 0"/>
    <limit effort="1.89" lower="-0.6108652381980153" upper="0.6108652381980153" velocity="6.544984694978735"/>
    <dynamics friction="0.0"/>
  </joint>
  <gazebo reference="coxa_5">
    <material>Gazebo/LightGrey</material>
  </gazebo>
  <gazebo reference="tc_5">
    <provideFeedback>true</provideFeedback>
  </gazebo>
  <gazebo>
    <plugin filename="libgazebo_ros_ft_sensor.so" name="torque_sensor_tc_5">
      <updateRate>50.0</updateRate>
      <topicName>torque_tc_5</topicName>
      <jointName>tc_5</jointName>
    </plugin>
  </gazebo>
  <transmission name="j_tc_5">
    <type>transmission_interface/SimpleTransmission</type>
    <joint name="tc_5">
      <hardwareInterface>hardware_interface/EffortJointInterface</hardwareInterface>
    </joint>
    <actuator name="motor_tc_5">
      <hardwareInterface>hardware_interface/EffortJointInterface</hardwareInterface>
      <mechanicalReduction>1</mechanicalReduction>
    </actuator>
  </transmission>
  <link name="femur_5">
    <visual>
      <origin rpy="0 0 0" xyz="0.04 0 0"/>
      <geometry>
        <box size="0.08 0.04 0.04"/>
      </geometry>
    </visual>
    <collision>
      <origin rpy="0 0 0" xyz="0.04 0 0"/>
      <geometry>
        <box size="0.08 0.04 0.04"/>
      </geometry>
    </collision>
    <inertial>
      <origin rpy="0 0 0" xyz="0.04 0 0"/>
      <mass value="0.136"/>
      <inertia ixx="0.0000362667" ixy="0.0" ixz="0.0" iyy="0.0000906667" iyz="0.0" izz="0.0000906667"/>
    </inertial>
  </link>
  <joint name="ctr_5" type="revolute">
    <axis xyz="0 -1 0"/>
    <parent link="coxa_5"/>
    <child link="femur_5"/>
    <origin rpy="0 0 0" xyz="0.063875 0 0"/>
    <limit effort="1.89" lower="-1.4835298641951802" upper="1.4835298641951802" velocity="6.544984694978735"/>
    <dynamics friction="0.0"/>
  </joint>
  <gazebo reference="femur_5">
    <material>Gazebo/LightGrey</material>
  </gazebo>
  <gazebo reference="ctr_5">
    <provideFeedback>true</provideFeedback>
  </gazebo>
  <gazebo>
    <plugin filename="libgazebo_ros_ft_sensor.so" name="torque_sensor_ctr_5">
      <updateRate>50.0</updateRate>
      <topicName>torque_ctr_5</topicName>
      <jointName>ctr_5</jointName>
    </plugin>
  </gazebo>
  <transmission name="j_ctr_5">
    <type>transmission_interface/SimpleTransmission</type>
    <joint name="ctr_5">
      <hardwareInterface>hardware_interface/EffortJointInterface</hardwareInterface>
    </joint>
    <actuator name="motor_ctr_5">
      <hardwareInterface>hardware_interface/EffortJointInterface</hardwareInterface>
      <mechanicalReduction>1</mechanicalReduction>
    </actuator>
  </transmission>
  <link name="tibia_5">
    <visual>
      <origin rpy="0 0 0" xyz="0 0 -0.057154"/>
      <geometry>
        <box size="0.04 0.04 0.114308"/>
      </geometry>
    </visual>
    <collision>
      <origin rpy="0 0 0" xyz="0 0 -0.057154"/>
      <geometry>
        <box size="0.04 0.04 0.114308"/>
      </geometry>
    </collision>
    <inertial>
      <origin rpy="0 0 0" xyz="0 0 -0.057154"/>
      <mass value="0.01338"/>
      <inertia ixx="0.0000163529" ixy="0.0" ixz="0.0" iyy="0.0000163529" iyz="0.0" izz="0.000003568"/>
    </inertial>
  </link>
  <joint name="fti_5" type="revolute">
    <axis xyz="0 -1 0"/>
    <parent link="femur_5"/>
    <child link="tibia_5"/>
    <origin rpy="0 0 0" xyz="0.08 0 0"/>
    <limit effort="1.89" lower="-1.4835298641951802" upper="1.4835298641951802" velocity="6.544984694978735"/>
    <dynamics friction="0.0"/>
  </joint>
  <gazebo reference="tibia_5">
    <material>Gazebo/LightGrey</material>
  </gazebo>
  <gazebo reference="fti_5">
    <provideFeedback>true</provideFeedback>
  </gazebo>
  <gazebo>
    <plugin filename="libgazebo_ros_ft_sensor.so" name="torque_sensor_fti_5">
      <updateRate>50.0</updateRate>
      <topicName>torque_fti_5</topicName>
      <jointName>fti_5</jointName>
    </plugin>
  </gazebo>
  <transmission name="j_fti_5">
    <type>transmission_interface/SimpleTransmission</type>
    <joint name="fti_5">
      <hardwareInterface>hardware_interface/EffortJointInterface</hardwareInterface>
    </joint>
    <actuator name="motor_fti_5">
      <hardwareInterface>hardware_interface/EffortJointInterface</hardwareInterface>
      <mechanicalReduction>1</mechanicalReduction>
    </actuator>
  </transmission>
  <link name="foot_5">
    <visual>
      <origin rpy="0 0 0" xyz="0 0 0"/>
      <geometry>
        <sphere radius="0.02"/>
      </geometry>
    </visual>
    <collision>
      <origin rpy="0 0 0" xyz="0 0 0"/>
      <geometry>
        <sphere radius="0.02"/>
      </geometry>
    </collision>
    <inertial>
      <origin rpy="0 0 0" xyz="0 0 0"/>
      <mass value="0.00892"/>
      <inertia ixx="0.0000057088" ixy="0.0" ixz="0.0" iyy="0.0000057088" iyz="0.0" izz="0.0000057088"/>
    </inertial>
  </link>
  <joint name="foot_5_joint" type="fixed">
    <parent link="tibia_5"/>
    <child link="foot_5"/>
    <origin rpy="0 0 0" xyz="0 0 -0.134308"/>
  </joint>
  <gazebo reference="foot_5_joint">
    <disableFixedJointLumping>true</disableFixedJointLumping>
  </gazebo>
  <gazebo reference="foot_5">
    <kp>1e06</kp>
    <kd>1.0</kd>
    <maxVel>0.0</maxVel>
    <minDepth>0.003</minDepth>
    <material>Gazebo/LightGrey</material>
    <collision name="foot_5_collision">
      <geometry>
        <sphere>
          <radius>0.02</radius>
        </sphere>
      </geometry>
      <surface>
        <friction>
          <ode>
            <solver>
              <friction_model>cone_model</friction_model>
              <mu>1.0</mu>
            </solver>
          </ode>
        </friction>
      </surface>
    </collision>
    <!-- Bumper sensor for contact detection -->
    <sensor name="contact_sensor_5" type="contact">
      <always_on>true</always_on>
      <contact>
        <collision>foot_5_collision</collision>
      </contact>
      <plugin filename="libgazebo_ros_bumper.so" name="foot_5_plugin">
        <updateRate>50</updateRate>
        <always_on>true</always_on>
        <bumperTopicName>foot_5_bumper</bumperTopicName>
        <frameName>world</frameName>
      </plugin>
    </sensor>
  </gazebo>
  <link name="coxa_6">
    <visual>
      <origin rpy="0 0 0" xyz="0.0319375 0 0"/>
      <geometry>
        <box size="0.063875 0.04 0.04"/>
      </geometry>
    </visual>
    <collision>
      <origin rpy="0 0 0" xyz="0.0319375 0 0"/>
      <geometry>
        <box size="0.063875 0.04 0.04"/>
      </geometry>
    </collision>
    <inertial>
      <origin rpy="0 0 0" xyz="0.0319375 0 0"/>
      <mass value="0.081"/>
      <inertia ixx="0.0000216" ixy="0.0" ixz="0.0" iyy="0.0000383401" iyz="0.0" izz="0.0000383401"/>
    </inertial>
  </link>
  <joint name="tc_6" type="revolute">
    <axis xyz="0 0 1"/>
    <parent link="torso"/>
    <child link="coxa_6"/>
    <origin rpy="0 0 -0.7853981633974483" xyz="0.06 -0.1 0"/>
    <limit effort="1.89" lower="-0.6108652381980153" upper="0.6108652381980153" velocity="6.544984694978735"/>
    <dynamics friction="0.0"/>
  </joint>
  <gazebo reference="coxa_6">
    <material>Gazebo/LightGrey</material>
  </gazebo>
  <gazebo reference="tc_6">
    <provideFeedback>true</provideFeedback>
  </gazebo>
  <gazebo>
    <plugin filename="libgazebo_ros_ft_sensor.so" name="torque_sensor_tc_6">
      <updateRate>50.0</updateRate>
      <topicName>torque_tc_6</topicName>
      <jointName>tc_6</jointName>
    </plugin>
  </gazebo>
  <transmission name="j_tc_6">
    <type>transmission_interface/SimpleTransmission</type>
    <joint name="tc_6">
      <hardwareInterface>hardware_interface/EffortJointInterface</hardwareInterface>
    </joint>
    <actuator name="motor_tc_6">
      <hardwareInterface>hardware_interface/EffortJointInterface</hardwareInterface>
      <mechanicalReduction>1</mechanicalReduction>
    </actuator>
  </transmission>
  <link name="femur_6">
    <visual>
      <origin rpy="0 0 0" xyz="0.04 0 0"/>
      <geometry>
        <box size="0.08 0.04 0.04"/>
      </geometry>
    </visual>
    <collision>
      <origin rpy="0 0 0" xyz="0.04 0 0"/>
      <geometry>
        <box size="0.08 0.04 0.04"/>
      </geometry>
    </collision>
    <inertial>
      <origin rpy="0 0 0" xyz="0.04 0 0"/>
      <mass value="0.136"/>
      <inertia ixx="0.0000362667" ixy="0.0" ixz="0.0" iyy="0.0000906667" iyz="0.0" izz="0.0000906667"/>
    </inertial>
  </link>
  <joint name="ctr_6" type="revolute">
    <axis xyz="0 -1 0"/>
    <parent link="coxa_6"/>
    <child link="femur_6"/>
    <origin rpy="0 0 0" xyz="0.063875 0 0"/>
    <limit effort="1.89" lower="-1.4835298641951802" upper="1.4835298641951802" velocity="6.544984694978735"/>
    <dynamics friction="0.0"/>
  </joint>
  <gazebo reference="femur_6">
    <material>Gazebo/LightGrey</material>
  </gazebo>
  <gazebo reference="ctr_6">
    <provideFeedback>true</provideFeedback>
  </gazebo>
  <gazebo>
    <plugin filename="libgazebo_ros_ft_sensor.so" name="torque_sensor_ctr_6">
      <updateRate>50.0</updateRate>
      <topicName>torque_ctr_6</topicName>
      <jointName>ctr_6</jointName>
    </plugin>
  </gazebo>
  <transmission name="j_ctr_6">
    <type>transmission_interface/SimpleTransmission</type>
    <joint name="ctr_6">
      <hardwareInterface>hardware_interface/EffortJointInterface</hardwareInterface>
    </joint>
    <actuator name="motor_ctr_6">
      <hardwareInterface>hardware_interface/EffortJointInterface</hardwareInterface>
      <mechanicalReduction>1</mechanicalReduction>
    </actuator>
  </transmission>
  <link name="tibia_6">
    <visual>
      <origin rpy="0 0 0" xyz="0 0 -0.057154"/>
      <geometry>
        <box size="0.04 0.04 0.114308"/>
      </geometry>
    </visual>
    <collision>
      <origin rpy="0 0 0" xyz="0 0 -0.057154"/>
      <geometry>
        <box size="0.04 0.04 0.114308"/>
      </geometry>
    </collision>
    <inertial>
      <origin rpy="0 0 0" xyz="0 0 -0.057154"/>
      <mass value="0.01338"/>
      <inertia ixx="0.0000163529" ixy="0.0" ixz="0.0" iyy="0.0000163529" iyz="0.0" izz="0.000003568"/>
    </inertial>
  </link>
  <joint name="fti_6" type="revolute">
    <axis xyz="0 -1 0"/>
    <parent link="femur_6"/>
    <child link="tibia_6"/>
    <origin rpy="0 0 0" xyz="0.08 0 0"/>
    <limit effort="1.89" lower="-1.4835298641951802" upper="1.4835298641951802" velocity="6.544984694978735"/>
    <dynamics friction="0.0"/>
  </joint>
  <gazebo reference="tibia_6">
    <material>Gazebo/LightGrey</material>
  </gazebo>
  <gazebo reference="fti_6">
    <provideFeedback>true</provideFeedback>
  </gazebo>
  <gazebo>
    <plugin filename="libgazebo_ros_ft_sensor.so" name="torque_sensor_fti_6">
      <updateRate>50.0</updateRate>
      <topicName>torque_fti_6</topicName>
      <jointName>fti_6</jointName>
    </plugin>
  </gazebo>
  <transmission name="j_fti_6">
    <type>transmission_interface/SimpleTransmission</type>
    <joint name="fti_6">
      <hardwareInterface>hardware_interface/EffortJointInterface</hardwareInterface>
    </joint>
    <actuator name="motor_fti_6">
      <hardwareInterface>hardware_interface/EffortJointInterface</hardwareInterface>
      <mechanicalReduction>1</mechanicalReduction>
    </actuator>
  </transmission>
  <link name="foot_6">
    <visual>
      <origin rpy="0 0 0" xyz="0 0 0"/>
      <geometry>
        <sphere radius="0.02"/>
      </geometry>
    </visual>
    <collision>
      <origin rpy="0 0 0" xyz="0 0 0"/>
      <geometry>
        <sphere radius="0.02"/>
      </geometry>
    </collision>
    <inertial>
      <origin rpy="0 0 0" xyz="0 0 0"/>
      <mass value="0.00892"/>
      <inertia ixx="0.0000057088" ixy="0.0" ixz="0.0" iyy="0.0000057088" iyz="0.0" izz="0.0000057088"/>
    </inertial>
  </link>
  <joint name="foot_6_joint" type="fixed">
    <parent link="tibia_6"/>
    <child link="foot_6"/>
    <origin rpy="0 0 0" xyz="0 0 -0.134308"/>
  </joint>
  <gazebo reference="foot_6_joint">
    <disableFixedJointLumping>true</disableFixedJointLumping>
  </gazebo>
  <gazebo reference="foot_6">
    <kp>1e06</kp>
    <kd>1.0</kd>
    <maxVel>0.0</maxVel>
    <minDepth>0.003</minDepth>
    <material>Gazebo/LightGrey</material>
    <collision name="foot_6_collision">
      <geometry>
        <sphere>
          <radius>0.02</radius>
        </sphere>
      </geometry>
      <surface>
        <friction>
          <ode>
            <solver>
              <friction_model>cone_model</friction_model>
              <mu>1.0</mu>
            </solver>
          </ode>
        </friction>
      </surface>
    </collision>
    <!-- Bumper sensor for contact detection -->
    <sensor name="contact_sensor_6" type="contact">
      <always_on>true</always_on>
      <contact>
        <collision>foot_6_collision</collision>
      </contact>
      <plugin filename="libgazebo_ros_bumper.so" name="foot_6_plugin">
        <updateRate>50</updateRate>
        <always_on>true</always_on>
        <bumperTopicName>foot_6_bumper</bumperTopicName>
        <frameName>world</frameName>
      </plugin>
    </sensor>
  </gazebo>
</robot>

